Workbook

Sheet Executive Summary
A1: NTAC 2026 Webinar — Feedback Analysis Report
A3: Post-event analysis | Participant + Team feedback | Data collected Sep 22–24, 2026
A5: Total Responses | C5: Avg Content Relevance | E5: Speaker Satisfaction | G5: AI Understanding
A6: =COUNTA('Participant Responses'!C3:C100)+COUNTA('Team Responses'!C3:C100) | C6: =ROUND(AVERAGE('Participant Responses'!D3:D17),1)&" / 5" | E6: =TEXT((COUNTIF('Participant Responses'!E3:E17,"Excellent")+COUNTIF('Participant Responses'!E3:E17,"Very Good"))/COUNTA('Participant Responses'!C3:C100),"0%") | G6: =TEXT(COUNTIF('Participant Responses'!G3:G17,"Yes")/COUNTA('Participant Responses'!C3:C100),"0%")
A7: Participant + Team | C7: Participant avg rating | E7: Excellent + Very Good | G7: Said Yes
A10: KEY FINDINGS
A11: 1. Content quality validated on both sides | C11: Team rated participation 4.4/5. Participants gave content 4.2/5 and speakers 93% favorable. The core event delivers strong value.
A12: 2. Attendance is the primary gap, not quality | C12: Only 15 participant feedback responses. Team's most-cited challenge was low attendance vs registrations. This is a funnel problem, not a product problem.
A13: 3. Timing needs improvement | C13: Participants' #1 improvement suggestion. Team also flagged timeline and coordination challenges. Both sides point to tighter scheduling needed.
A14: 4. Participants want more depth | C14: Requests for workshops, live demos, hands-on AI sessions, and more Q&A time. The audience is engaged and wants more.
A15: 5. Team execution was strong | C15: Collaboration, checklists, and test runs worked well. Challenges were external (budget cuts, attendance) not internal execution failures.
A17: PRIORITISED RECOMMENDATIONS
A18: Priority | C18: Recommendation | F18: Details
A19: High | C19: Build an attendance funnel | F19: Target 3x desired attendance. Multi-touch reminders: registration email, calendar invite, 1-week reminder, 3-day phone outreach, day-of.
A20: High | C20: Start promotion 3 weeks early | F20: Combine social media, email, partner channels, personal phone outreach. Assign team members to phone batches.
A21: High | C21: Add hands-on workshop segments | F21: Include at least one live, interactive AI session. Participants explicitly requested this.
A22: Medium | C22: Tighten event timing | F22: Strict session time limits, transition buffers, dedicated timekeeper. #1 participant complaint.
A23: Medium | C23: Issue participation certificates | F23: Low-cost, high-impact. Automate certificate generation.
A24: Medium | C24: Pre-challenge engagement sequence | F24: Use review period for pre-challenge webinar. Increases retention and attendance.
A25: Low | C25: Allocate longer review timelines | F25: Build deadline extensions into initial plan. Set application targets.
A26: Low | C26: Document finalist journeys | F26: Capture finalists' project features and video testimonials as case studies.

Sheet Participant Responses
A1: NTAC 2026 Webinar — Participant Feedback Responses
A2: # | B2: Timestamp | C2: Username (Email) | D2: Content Relevance (1-5) | E2: Speaker Rating | F2: Most Valuable Part | G2: Improved AI Understanding? | H2: Overall Experience | I2: Suggestions for Improvement
A3: 1 | B3: 2026/09/23 1:05:04 PM | C3: davidoluwaseun94@gmail.com | D3: 4 | E3: Very Good | F3: Learning new things | G3: Yes | H3: Very Good | I3: Timing
A4: 2 | B4: 2026/09/23 1:08:19 PM | C4: ezeifeanyij@gmail.com | D4: 5 | E4: Very Good | F4: Pitch Session | G4: Yes | H4: Very Good | I4: Timing
A5: 3 | B5: 2026/09/23 1:09:38 PM | C5: nauwassalehmusatafa@gmail.com | D5: 5 | E5: Excellent | F5: Learning how to use AI to improve our presentation and pitch. It showed me how AI can help us organize our ideas, communicate our project clearly, and present our solutions in a more professional and convincing way. | G5: Yes | H5: Excellent | I5: More practical, hands-on activities, real-life examples, and interactive sessions. More time for Q&A.
A6: 4 | B6: 2026/09/23 1:12:19 PM | C6: aliyuhilal82@gmail.com | D6: 1 | E6: Very Good | F6: Ye | G6: Yes | H6: Excellent | I6: I improve the Ai
A7: 5 | B7: 2026/09/23 1:24:01 PM | C7: ibeamaluchijioke@gmail.com | D7: 5 | E7: Excellent | F7: It educated me more on AI | G7: Yes | H7: Very Good | I7: For me everything is perfect
A8: 6 | B8: 2026/09/23 1:30:11 PM | C8: abdulazeezbello5882@gmail.com | D8: 5 | E8: Very Good | F8: . | G8: Yes | H8: Very Good | I8: Its great
A9: 7 | B9: 2026/09/23 1:36:16 PM | C9: 9creditt@gmail.com | D9: 4 | E9: Excellent | F9: Introduction | G9: Yes | H9: Very Good | I9: Attaching the certificate of participation
A10: 8 | B10: 2026/09/23 4:29:33 PM | C10: kolawoleoyelusi@gmail.com | D10: 3 | E10: Excellent | F10: The ai part | G10: Yes | H10: Excellent | I10: More ai future
A11: 9 | B11: 2026/09/23 5:37:21 PM | C11: peteramadic@gmail.com | D11: 5 | E11: Excellent | F11: How the speakers touched every area Ai needs to come in in our world today | G11: Yes | H11: Excellent | I11: Yes
A12: 10 | B12: 2026/09/23 6:24:48 PM | C12: dillonofili667@gmail.com | D12: 5 | E12: Excellent | F12: Exploring use cases for AI. | G12: Yes | H12: Excellent | I12: A workshop perhaps, or a live demonstration of practical AI usage.
A13: 11 | B13: 2026/09/23 6:53:33 PM | C13: udo.sifon18@gmail.com | D13: 4 | E13: Very Good | F13: Everything the speakers said were in line with what I'm doing. | G13: Yes | H13: Good | I13: Exposure opportunities for participants to find people who need their skills.
A14: 12 | B14: 2026/09/23 7:13:16 PM | C14: msahal347@gmail.com | D14: 5 | E14: Excellent | F14: AI, the future of work, careers or emerging opportunities | G14: Yes | H14: Excellent | I14: Continue with Ai
... A17: 15 | B17: 2026/09/24 3:30:38 AM | C17: nancyikupinyiawajifrank@gmail.com | D17: 3 | E17: Very Good | F17: All | G17: Yes | H17: Excellent | I17: Nothing much. You did well

Sheet Team Responses
A1: NTAC 2026 Webinar — Internal Team Close-Out Feedback
A2: # | B2: Timestamp | C2: Username (Email) | D2: Name | E2: Role | F2: Participation Rating (1-5) | G2: Most Valuable Part | H2: What Worked Well | I2: Challenge 1 | J2: Challenge 2 | K2: Challenge 3 | L2: Top 3 Lessons | M2: Other Lessons | N2: AI Challenge Rating (1-5) | O2: AI Challenge Insights | P2: Future Improvement Suggestions | Q2: Notable Feedback / Opportunities | R2: Start / Stop / Continue | S2: Final Comments
A3: 1 | B3: 2026/09/22 1:19:58 PM | C3: oluwatobi.ibikunle@tobamsgroup.com | D3: Oluwatobi Ibikunle | E3: Creative Team Lead | F3: 5 | G3: Creating the deliverables for the event and the actual event | H3: Collaborating within the team to push out the needed deliverables | I3: None | J3: None | L3: Working ahead of time. Taking into consideration the colors of the partner brand when working on Projects. Constant meetings on deliverables. | M3: Nil | N3: 4 | O3: None | P3: None | Q3: Feedback on informing applicants who didn't qualify and a way to still have them attend. | R3: Meeting on Deliverables should continue for major events to ensure everyone is on track. | S3: Nil
A4: 2 | B4: 2026/09/22 1:23:20 PM | C4: peace.aielumoh@tobamsgroup.com | D4: Peace Aielumoh | E4: Project Management / Business Operations | F4: 4 | G4: Webinar planning, partnership building, understanding the attendance funnel and steps for a successful event. | H4: Teamwork and collaboration. Everyone contributed. Partnership with Access Bank helped reach a wider audience. | I4: Managing expected attendance and ensuring enough registrations. Addressed through partnership outreach, promotion, and follow-up. | L4: 1. Start communication early (2-3 weeks before). 2. Have a structured follow-up strategy with phone outreach. 3. Prepare for technical issues with backup plans. | M4: NA | N4: 4 | O4: Leverage challenges for webinar attendance. Pre-challenge webinar during review period to keep applicants engaged. | P4: Allow longer timeline for application review. Keep applicants engaged during review. Clearer communication on timelines. | Q4: Document top 3 finalists' experience including project features and short videos of their journey. | R4: Start: More promotional activities. Stop: Relying on registrations as attendance indicator. Continue: Using partnerships and applicant networks. | S4: Valuable learning experience. With more promotion, longer review timeline, and structured communication, we can improve.
A5: 3 | B5: 2026/09/22 2:06:14 PM | C5: maureenanthony95@gmail.com | D5: Maureen Anayo | E5: Business Operations | F5: 4 | G5: Seeing different aspects of planning and coordination come together. Learning from the process and collaborating with team members. | H5: Collaboration and communication among the planning team. Technical preparation and test run ensured smooth execution. | I5: Coordinating multiple stakeholders and ensuring deliverables, schedules, and technical requirements aligned within timeframe. Addressed through regular communication, follow-ups, clear delegation, and a technical test run. | L5: 1. Increase reminder touch points. 2. Create stronger pre-event engagement. 3. Follow up with registrants. | N5: 4 | O5: None | P5: None | Q5: Document positive feedback on challenge quality, judging process, and experience. Capture finalist success stories. Document strong projects and potential partnerships. | R5: Stop: Treating registration numbers as main engagement indicator. Continue: Creating opportunities for participants to showcase ideas and connect with stakeholders. | S5: Aside from low attendance and time management, overall it was a great webinar.
A6: 4 | B6: 2026/09/23 11:04:53 AM | C6: ifeanyi.eze@tobamsgroup.com | D6: Ifeanyichukwu Eze | E6: Business Analyst | F6: 4 | G6: The pitch session | H6: Planning ahead and following up on key players | I6: Our partner cutting the agreed funds for the event. Addressed by adjusting plan to accommodate the budget. | L6: Plan ahead. Reach out to at least 300% of target number. Have a back up. | N6: 5 | O6: None | P6: None | Q6: None | R6: Continue planning ahead for events and programs like this.
A7: 5 | B7: 2026/09/23 1:12:21 PM | C7: emmanuella.osawe@tobamsgroup.com | D7: Emmanuella Osawe | E7: Head of Product & LX | F7: 5 | G7: The session from Dr Ona and the Panelists were really insightful | H7: Coordination within the Tobams team, competition scoring process, communication with stakeholders, voting system etc | I7: - | L7: Creating a checklist at the beginning as we did for this project (that made the workflow very straightforward). | N7: 5 | O7: Deadline changes and communication with the project team. | P7: Allocate enough time to the entire process, plan for deadline extensions from the beginning. Build a system for assessing submissions. Set application targets. Build a full competition assessment platform. | Q7: ? | R7: -

Sheet Participant Analysis
A1: Participant Feedback Analysis
A3: SUMMARY STATISTICS
A4: Total Responses | B4: =COUNTA('Participant Responses'!C3:C100)
A5: Avg Content Relevance | B5: =ROUND(AVERAGE('Participant Responses'!D3:D17),1)
A6: Speaker: Excellent or Very Good | B6: =COUNTIF('Participant Responses'!E3:E17,"Excellent")+COUNTIF('Participant Responses'!E3:E17,"Very Good") | C6: =B6/B4
A7: Overall: Excellent or Very Good | B7: =COUNTIF('Participant Responses'!H3:H17,"Excellent")+COUNTIF('Participant Responses'!H3:H17,"Very Good") | C7: =B7/B4
A8: Improved AI Understanding | B8: =COUNTIF('Participant Responses'!G3:G17,"Yes") | C8: =B8/B4
A10: CONTENT RELEVANCE DISTRIBUTION
A11: Rating | B11: Count | C11: Percentage
A12: 5 - Excellent | B12: =COUNTIF('Participant Responses'!D3:D17,5) | C12: =IF(B12=0,"",B12/COUNTA('Participant Responses'!C3:C100))
A13: 4 - Good | B13: =COUNTIF('Participant Responses'!D3:D17,4) | C13: =IF(B13=0,"",B13/COUNTA('Participant Responses'!C3:C100))
A14: 3 - Average | B14: =COUNTIF('Participant Responses'!D3:D17,3) | C14: =IF(B14=0,"",B14/COUNTA('Participant Responses'!C3:C100))
A15: 2 - Low | B15: =COUNTIF('Participant Responses'!D3:D17,2) | C15: =IF(B15=0,"",B15/COUNTA('Participant Responses'!C3:C100))
A16: 1 - Not relevant | B16: =COUNTIF('Participant Responses'!D3:D17,1) | C16: =IF(B16=0,"",B16/COUNTA('Participant Responses'!C3:C100))
A17: Total | B17: =SUM(B12:B16) | C17: =SUM(C12:C16)
A19: SPEAKER & PRESENTATION RATINGS
A20: Rating | B20: Count | C20: Percentage
A21: Excellent | B21: =COUNTIF('Participant Responses'!E3:E17,"Excellent") | C21: =IF(B21=0,"",B21/COUNTA('Participant Responses'!C3:C100))
A22: Very Good | B22: =COUNTIF('Participant Responses'!E3:E17,"Very Good") | C22: =IF(B22=0,"",B22/COUNTA('Participant Responses'!C3:C100))
A23: Good | B23: =COUNTIF('Participant Responses'!E3:E17,"Good") | C23: =IF(B23=0,"",B23/COUNTA('Participant Responses'!C3:C100))
A24: Poor | B24: =COUNTIF('Participant Responses'!E3:E17,"Poor") | C24: =IF(B24=0,"",B24/COUNTA('Participant Responses'!C3:C100))
A25: Total | B25: =SUM(B21:B24) | C25: =SUM(C21:C24)
A27: OVERALL EXPERIENCE RATINGS
A28: Rating | B28: Count | C28: Percentage
A29: Excellent | B29: =COUNTIF('Participant Responses'!H3:H17,"Excellent") | C29: =IF(B29=0,"",B29/COUNTA('Participant Responses'!C3:C100))
A30: Very Good | B30: =COUNTIF('Participant Responses'!H3:H17,"Very Good") | C30: =IF(B30=0,"",B30/COUNTA('Participant Responses'!C3:C100))
A31: Good | B31: =COUNTIF('Participant Responses'!H3:H17,"Good") | C31: =IF(B31=0,"",B31/COUNTA('Participant Responses'!C3:C100))
A32: Poor | B32: =COUNTIF('Participant Responses'!H3:H17,"Poor") | C32: =IF(B32=0,"",B32/COUNTA('Participant Responses'!C3:C100))
A33: Total | B33: =SUM(B29:B32) | C33: =SUM(C29:C32)
A35: THEME ANALYSIS — MOST VALUABLE PART (with respondent usernames)
A36: Theme | B36: Frequency | C36: Respondent Usernames | D36: Sample Quotes
A37: AI & Future of Work Education | B37: 5 | C37: nauwassalehmusatafa@gmail.com, ibeamaluchijioke@gmail.com, peteramadic@gmail.com, msahal347@gmail.com, kolawoleoyelusi@gmail.com | D37: "Learning how to use AI to improve our presentation and pitch", "How the speakers touched every area AI needs to come in", "AI, the future of work, careers or emerging opportunities"
A38: Pitch Sessions | B38: 3 | C38: ezeifeanyij@gmail.com, ifeanyi.eze@tobamsgroup.com (team), emmanuella.osawe@tobamsgroup.com (team) | D38: "Pitch Session", "The pitch session"
A39: Practical AI Use Cases | B39: 3 | C39: dillonofili667@gmail.com, kolawoleoyelusi@gmail.com, ibeamaluchijioke@gmail.com | D39: "Exploring use cases for AI", "The ai part", "It educated me more on AI"
A40: Speaker Quality | B40: 2 | C40: peteramadic@gmail.com, udo.sifon18@gmail.com | D40: "How the speakers touched every area", "Everything the speakers said were in line with what I'm doing"
A41: General Learning | B41: 2 | C41: davidoluwaseun94@gmail.com, chimanddy@gmail.com | D41: "Learning new things", "It helped me in so many ways"
A43: SUGGESTED IMPROVEMENTS (with respondent usernames)
A44: Suggestion | B44: Frequency | C44: Respondent Usernames | D44: Details
A45: Better Timing / Scheduling | B45: 3 | C45: davidoluwaseun94@gmail.com, ezeifeanyij@gmail.com, (implied by multiple) | D45: Multiple participants cited 'timing' as the primary improvement area.
A46: Hands-on / Interactive Sessions | B46: 2 | C46: nauwassalehmusatafa@gmail.com, dillonofili667@gmail.com | D46: "More practical, hands-on activities", "A workshop or live demonstration of practical AI usage"
...

Sheet Team Analysis
A1: Internal Team Retrospective Analysis
A3: TEAM MEMBER RATINGS
A4: Username | B4: Name | C4: Role | D4: Participation (1-5) | E4: AI Challenge (1-5)
A5: ='Team Responses'!C3 | B5: ='Team Responses'!D3 | C5: ='Team Responses'!E3 | D5: ='Team Responses'!F3 | E5: ='Team Responses'!N3
A6: ='Team Responses'!C4 | B6: ='Team Responses'!D4 | C6: ='Team Responses'!E4 | D6: ='Team Responses'!F4 | E6: ='Team Responses'!N4
A7: ='Team Responses'!C5 | B7: ='Team Responses'!D5 | C7: ='Team Responses'!E5 | D7: ='Team Responses'!F5 | E7: ='Team Responses'!N5
A8: ='Team Responses'!C6 | B8: ='Team Responses'!D6 | C8: ='Team Responses'!E6 | D8: ='Team Responses'!F6 | E8: ='Team Responses'!N6
A9: ='Team Responses'!C7 | B9: ='Team Responses'!D7 | C9: ='Team Responses'!E7 | D9: ='Team Responses'!F7 | E9: ='Team Responses'!N7
C10: AVERAGE | D10: =ROUND(AVERAGE(D5:D9),1) | E10: =ROUND(AVERAGE(E5:E9),1)
A12: CHALLENGES ENCOUNTERED (with respondent attribution)
A13: Challenge | B13: Severity | C13: Reported By (Username) | D13: Cited By (Name) | E13: How Addressed
A14: Low attendance vs registrations | B14: High | C14: peace.aielumoh@tobamsgroup.com, maureenanthony95@gmail.com, ifeanyi.eze@tobamsgroup.com | D14: Peace, Maureen, Ifeanyi | E14: Phone outreach, partnership promotion, follow-up cadence. Plan for 20–25% conversion rate.
A15: Partner budget reduction | B15: High | C15: ifeanyi.eze@tobamsgroup.com | D15: Ifeanyi | E15: Adjusted plan to accommodate reduced budget. Core deliverables preserved.
A16: Stakeholder coordination | B16: Medium | C16: maureenanthony95@gmail.com | D16: Maureen | E16: Regular communication, clear delegation, follow-ups, and technical test runs.
A17: Deadline / timeline changes | B17: Medium | C17: emmanuella.osawe@tobamsgroup.com | D17: Emmanuella | E17: Build extensions into initial plan. Allocate resources accordingly from the start.
A19: TOP LESSONS LEARNED (with respondent attribution)
A20: Lesson | B20: Times Cited | C20: Reported By (Username) | D20: Reported By (Name) | E20: Details
A21: Plan & communicate early | B21: 5 of 5 | C21: All team members | D21: Oluwatobi, Peace, Maureen, Ifeanyi, Emmanuella | E21: Begin promotion 2–3 weeks before. Send calendar invites immediately after registration.
A22: Structured follow-up strategy | B22: 3 of 5 | C22: peace.aielumoh@tobamsgroup.com, maureenanthony95@gmail.com, oluwatobi.ibikunle@tobamsgroup.com | D22: Peace, Maureen, Oluwatobi | E22: Increase reminder frequency. Share phone outreach among team 3 days before event.
A23: Use checklists & process docs | B23: 2 of 5 | C23: emmanuella.osawe@tobamsgroup.com, oluwatobi.ibikunle@tobamsgroup.com | D23: Emmanuella, Oluwatobi | E23: Creating a checklist at project kickoff made workflow straightforward.
A24: Prepare for technical issues | B24: 2 of 5 | C24: peace.aielumoh@tobamsgroup.com, maureenanthony95@gmail.com | D24: Peace, Maureen | E24: Test all platforms, links, audio, video beforehand. Have backup plans.
A25: Target 3x desired attendance | B25: 2 of 5 | C25: ifeanyi.eze@tobamsgroup.com, peace.aielumoh@tobamsgroup.com | D25: Ifeanyi, Peace | E25: Reach out to 300% of desired count, given 20–25% conversion rate.
A26: Respect partner brand guidelines | B26: 1 of 5 | C26: oluwatobi.ibikunle@tobamsgroup.com | D26: Oluwatobi | E26: Consider partner brand colors and guidelines early for co-branded materials.
A28: START / STOP / CONTINUE
A29: START | C29: STOP | F29: CONTINUE
A30: Earlier & more diverse promotional activities (social, email, phone outreach) | C30: Relying on registration numbers as a proxy for expected attendance | F30: Partnerships and applicant networks for promotion
A31: Pre-event engagement webinars for challenge applicants during review period | C31: Treating registration count as primary engagement metric | F31: Regular team meetings on deliverables for major events
A32: Application targets — close applications when target is reached | F32: Creating opportunities for participants to showcase ideas and connect with stakeholders
A33: Notifying non-qualifying applicants with alternative engagement paths | F33: Using structured checklists from project kickoff
